# 문제2. 협업 시 충돌 – 동일 위치 충돌
* 로컬 app.py에 아래 코드를 추가하고 커밋한다.
```python
@app.route("/test1")
def test1():
    return render_template('test1.html')
```

* GitHub 웹에서도 동일 위치에 아래 코드를 추가하고 커밋한다.
```python
@app.route("/test2")
def test2():
    return render_template('test2.html')
```

```bash
sh-5.2$ git push origin merge-menu  push 해봐야 에러만 난다
To https://github.com/nttkor/david.git
 ! [rejected]        merge-menu -> merge-menu (fetch first)
error: failed to push some refs to 'https://github.com/nttkor/david.git'
hint: Updates were rejected because the remote contains work that you do not
hint: have locally. This is usually caused by another repository pushing to
hint: the same ref. If you want to integrate the remote changes, use
hint: 'git pull' before pushing again.
hint: See the 'Note about fast-forwards' in 'git push --help' for details.
```
pull 도 해봐야 conflict때문에 다시 에러 결국 머지로 해결해야 한다. rebase는 새로은 commit을 만드므로 별로 않좋다.
git pull --no-rebase origin merge-menu

conflic를 만들때 동일 위치일 경우 매뉴얼로 편집해야하고 add commit까지 끝내야 한다
자동은 push만 해도 됨

| 단계           | 필요 여부    | 설명                 |
| ------------ | -------- | ------------------ |
| `git add`    | ❌ 안 해도 됨 | 병합 커밋이 자동 생성되었기 때문 |
| `git commit` | ❌ 필요 없음  | 이미 병합 커밋이 완료됨      |
| `git push`   | ✅ 꼭 해야 함 | 병합 결과를 GitHub에 반영  |
